Workbook

Sheet Анализ КБ
A1: Клиент | B1: Январь | D1: Февраль | F1: Март | H1: 3 мес | I1: Апрель | K1: Май | M1: Июнь | O1: 3 мес | P1: Июль | R1: Август | T1: Сентябрь | V1: 3 мес | W1: Октябрь | Y1: Ноябрь | AA1: Декабрь | AC1: 3 мес | AD1: год
B2: 1 | C2: 2 | D2: 1 | E2: 2 | F2: 1 | G2: 2 | I2: 1 | J2: 2 | K2: 1 | L2: 2 | M2: 1 | N2: 2 | P2: 1 | Q2: 2 | R2: 1 | S2: 2 | T2: 1 | U2: 2 | W2: 1 | X2: 2 | Y2: 1 | Z2: 2 | AA2: 1 | AB2: 2
A3: Клиент | H3: =SUM(B3:G3) -> 0 | O3: =SUM(I3:N3) -> 0 | V3: =SUM(P3:U3) -> 0 | AC3: =SUM(W3:AB3) -> 0 | AD3: =SUM(H3+O3+V3+AC3) -> 0
A4: Клиент | H4: =SUM(B4:G4) -> 0 | O4: =SUM(I4:N4) -> 0 | V4: =SUM(P4:U4) -> 0 | AC4: =SUM(W4:AB4) -> 0 | AD4: =SUM(H4+O4+V4+AC4) -> 0
A5: Клиент | H5: =SUM(B5:G5) -> 0 | O5: =SUM(I5:N5) -> 0 | V5: =SUM(P5:U5) -> 0 | AC5: =SUM(W5:AB5) -> 0 | AD5: =SUM(H5+O5+V5+AC5) -> 0
A6: Клиент | H6: =SUM(B6:G6) -> 0 | O6: =SUM(I6:N6) -> 0 | V6: =SUM(P6:U6) -> 0 | AC6: =SUM(W6:AB6) -> 0 | AD6: =SUM(H6+O6+V6+AC6) -> 0
A7: Клиент | H7: =SUM(B7:G7) -> 0 | O7: =SUM(I7:N7) -> 0 | V7: =SUM(P7:U7) -> 0 | AC7: =SUM(W7:AB7) -> 0 | AD7: =SUM(H7+O7+V7+AC7) -> 0
A8: Клиент | H8: =SUM(B8:G8) -> 0 | O8: =SUM(I8:N8) -> 0 | V8: =SUM(P8:U8) -> 0 | AC8: =SUM(W8:AB8) -> 0 | AD8: =SUM(H8+O8+V8+AC8) -> 0
A9: Клиент | H9: =SUM(B9:G9) -> 0 | O9: =SUM(I9:N9) -> 0 | V9: =SUM(P9:U9) -> 0 | AC9: =SUM(W9:AB9) -> 0 | AD9: =SUM(H9+O9+V9+AC9) -> 0
A10: Клиент | H10: =SUM(B10:G10) -> 0 | O10: =SUM(I10:N10) -> 0 | V10: =SUM(P10:U10) -> 0 | AC10: =SUM(W10:AB10) -> 0 | AD10: =SUM(H10+O10+V10+AC10) -> 0
A11: Клиент | H11: =SUM(B11:G11) -> 0 | O11: =SUM(I11:N11) -> 0 | V11: =SUM(P11:U11) -> 0 | AC11: =SUM(W11:AB11) -> 0 | AD11: =SUM(H11+O11+V11+AC11) -> 0
A12: Клиент | H12: =SUM(B12:G12) -> 0 | O12: =SUM(I12:N12) -> 0 | V12: =SUM(P12:U12) -> 0 | AC12: =SUM(W12:AB12) -> 0 | AD12: =SUM(H12+O12+V12+AC12) -> 0
A13: Клиент | H13: =SUM(B13:G13) -> 0 | O13: =SUM(I13:N13) -> 0 | V13: =SUM(P13:U13) -> 0 | AC13: =SUM(W13:AB13) -> 0 | AD13: =SUM(H13+O13+V13+AC13) -> 0
A14: Клиент | H14: =SUM(B14:G14) -> 0 | O14: =SUM(I14:N14) -> 0 | V14: =SUM(P14:U14) -> 0 | AC14: =SUM(W14:AB14) -> 0 | AD14: =SUM(H14+O14+V14+AC14) -> 0
... A150: Клиент | H150: =SUM(B150:G150) -> 0 | O150: =SUM(I150:N150) -> 0 | V150: =SUM(P150:U150) -> 0 | AC150: =SUM(W150:AB150) -> 0 | AD150: =SUM(H150+O150+V150+AC150) -> 0
A151: Итого: | B151: =SUM(B3:C150) -> 0 | D151: =SUM(D3:E150) -> 0 | F151: =SUM(F3:G150) -> 0 | H151: =SUM(H3:H150) -> 0 | I151: =SUM(I3:J150) -> 0 | K151: =SUM(K3:L150) -> 0 | M151: =SUM(M3:N150) -> 0 | O151: =SUM(O3:O150) -> 0 | P151: =SUM(P3:Q150) -> 0 | R151: =SUM(R3:S150) -> 0 | T151: =SUM(T3:U150) -> 0 | V151: =SUM(V3:V150) -> 0 | W151: =SUM(W3:X150) -> 0 | Y151: =SUM(Y3:Z150) -> 0 | AA151: =SUM(AA3:AB150) -> 0 | AC151: =SUM(AC3:AC150) -> 0

Sheet Себестоимость
A1: Материал | B1: Закупка | D1: Услуга 1 | F1: Услуга 2 | H1: Услуга 3 | J1: Услуга 4 | L1: Услуга 5 | N1: Услуга 6 | P1: Услуга 7 | R1: Услуга 8 | T1: Услуга 9 | V1: Услуга 10
B2: шт/гр | C2: руб | D2: шт/гр | E2: руб | F2: шт/гр | G2: руб | H2: шт/гр | I2: руб | J2: шт/гр | K2: руб | L2: шт/гр | M2: руб | N2: шт/гр | O2: руб | P2: шт/гр | Q2: руб | R2: шт/гр | S2: руб | T2: шт/гр | U2: руб | V2: шт/гр | W2: руб
A3: Материал | E3: =C3/B3*D3 -> #DIV/0! | G3: =C3/B3*F4 -> #DIV/0! | I3: =C3/B3*H3 -> #DIV/0! | K3: =C3/B3*J3 -> #DIV/0! | M3: =C3/B3*L3 -> #DIV/0! | O3: =C3/B3*N3 -> #DIV/0! | Q3: =C3/B3*P3 -> #DIV/0! | S3: =C3/B3*R3 -> #DIV/0! | U3: =C3/B3*T3 -> #DIV/0! | W3: =C3/B3*V3 -> #DIV/0!
A4: Материал | E4: =C4/B4*D4 -> #DIV/0! | G4: =C4/B4*F5 -> #DIV/0! | I4: =C4/B4*H4 -> #DIV/0! | K4: =C4/B4*J4 -> #DIV/0! | M4: =C4/B4*L4 -> #DIV/0! | O4: =C4/B4*N4 -> #DIV/0! | Q4: =C4/B4*P4 -> #DIV/0! | S4: =C4/B4*R4 -> #DIV/0! | U4: =C4/B4*T4 -> #DIV/0! | W4: =C4/B4*V4 -> #DIV/0!
A5: Материал | E5: =C5/B5*D5 -> #DIV/0! | G5: =C5/B5*F6 -> #DIV/0! | I5: =C5/B5*H5 -> #DIV/0! | K5: =C5/B5*J5 -> #DIV/0! | M5: =C5/B5*L5 -> #DIV/0! | O5: =C5/B5*N5 -> #DIV/0! | Q5: =C5/B5*P5 -> #DIV/0! | S5: =C5/B5*R5 -> #DIV/0! | U5: =C5/B5*T5 -> #DIV/0! | W5: =C5/B5*V5 -> #DIV/0!
A6: Материал | E6: =C6/B6*D6 -> #DIV/0! | G6: =C6/B6*F7 -> #DIV/0! | I6: =C6/B6*H6 -> #DIV/0! | K6: =C6/B6*J6 -> #DIV/0! | M6: =C6/B6*L6 -> #DIV/0! | O6: =C6/B6*N6 -> #DIV/0! | Q6: =C6/B6*P6 -> #DIV/0! | S6: =C6/B6*R6 -> #DIV/0! | U6: =C6/B6*T6 -> #DIV/0! | W6: =C6/B6*V6 -> #DIV/0!
A7: Материал | E7: =C7/B7*D7 -> #DIV/0! | G7: =C7/B7*F8 -> #DIV/0! | I7: =C7/B7*H7 -> #DIV/0! | K7: =C7/B7*J7 -> #DIV/0! | M7: =C7/B7*L7 -> #DIV/0! | O7: =C7/B7*N7 -> #DIV/0! | Q7: =C7/B7*P7 -> #DIV/0! | S7: =C7/B7*R7 -> #DIV/0! | U7: =C7/B7*T7 -> #DIV/0! | W7: =C7/B7*V7 -> #DIV/0!
A8: Материал | E8: =C8/B8*D8 -> #DIV/0! | G8: =C8/B8*F9 -> #DIV/0! | I8: =C8/B8*H8 -> #DIV/0! | K8: =C8/B8*J8 -> #DIV/0! | M8: =C8/B8*L8 -> #DIV/0! | O8: =C8/B8*N8 -> #DIV/0! | Q8: =C8/B8*P8 -> #DIV/0! | S8: =C8/B8*R8 -> #DIV/0! | U8: =C8/B8*T8 -> #DIV/0! | W8: =C8/B8*V8 -> #DIV/0!
A9: Материал | E9: =C9/B9*D9 -> #DIV/0! | G9: =C9/B9*F10 -> #DIV/0! | I9: =C9/B9*H9 -> #DIV/0! | K9: =C9/B9*J9 -> #DIV/0! | M9: =C9/B9*L9 -> #DIV/0! | O9: =C9/B9*N9 -> #DIV/0! | Q9: =C9/B9*P9 -> #DIV/0! | S9: =C9/B9*R9 -> #DIV/0! | U9: =C9/B9*T9 -> #DIV/0! | W9: =C9/B9*V9 -> #DIV/0!
A10: Материал | E10: =C10/B10*D10 -> #DIV/0! | G10: =C10/B10*F11 -> #DIV/0! | I10: =C10/B10*H10 -> #DIV/0! | K10: =C10/B10*J10 -> #DIV/0! | M10: =C10/B10*L10 -> #DIV/0! | O10: =C10/B10*N10 -> #DIV/0! | Q10: =C10/B10*P10 -> #DIV/0! | S10: =C10/B10*R10 -> #DIV/0! | U10: =C10/B10*T10 -> #DIV/0! | W10: =C10/B10*V10 -> #DIV/0!
A11: Материал | E11: =C11/B11*D11 -> #DIV/0! | G11: =C11/B11*F12 -> #DIV/0! | I11: =C11/B11*H11 -> #DIV/0! | K11: =C11/B11*J11 -> #DIV/0! | M11: =C11/B11*L11 -> #DIV/0! | O11: =C11/B11*N11 -> #DIV/0! | Q11: =C11/B11*P11 -> #DIV/0! | S11: =C11/B11*R11 -> #DIV/0! | U11: =C11/B11*T11 -> #DIV/0! | W11: =C11/B11*V11 -> #DIV/0!
A12: Материал | E12: =C12/B12*D12 -> #DIV/0! | G12: =C12/B12*F13 -> #DIV/0! | I12: =C12/B12*H12 -> #DIV/0! | K12: =C12/B12*J12 -> #DIV/0! | M12: =C12/B12*L12 -> #DIV/0! | O12: =C12/B12*N12 -> #DIV/0! | Q12: =C12/B12*P12 -> #DIV/0! | S12: =C12/B12*R12 -> #DIV/0! | U12: =C12/B12*T12 -> #DIV/0! | W12: =C12/B12*V12 -> #DIV/0!
A13: Материал | E13: =C13/B13*D13 -> #DIV/0! | G13: =C13/B13*F14 -> #DIV/0! | I13: =C13/B13*H13 -> #DIV/0! | K13: =C13/B13*J13 -> #DIV/0! | M13: =C13/B13*L13 -> #DIV/0! | O13: =C13/B13*N13 -> #DIV/0! | Q13: =C13/B13*P13 -> #DIV/0! | S13: =C13/B13*R13 -> #DIV/0! | U13: =C13/B13*T13 -> #DIV/0! | W13: =C13/B13*V13 -> #DIV/0!
A14: Материал | E14: =C14/B14*D14 -> #DIV/0! | G14: =C14/B14*F15 -> #DIV/0! | I14: =C14/B14*H14 -> #DIV/0! | K14: =C14/B14*J14 -> #DIV/0! | M14: =C14/B14*L14 -> #DIV/0! | O14: =C14/B14*N14 -> #DIV/0! | Q14: =C14/B14*P14 -> #DIV/0! | S14: =C14/B14*R14 -> #DIV/0! | U14: =C14/B14*T14 -> #DIV/0! | W14: =C14/B14*V14 -> #DIV/0!
... A58: Материал | E58: =C58/B58*D58 -> #DIV/0! | G58: =C58/B58*F59 -> #DIV/0! | I58: =C58/B58*H58 -> #DIV/0! | K58: =C58/B58*J58 -> #DIV/0! | M58: =C58/B58*L58 -> #DIV/0! | O58: =C58/B58*N58 -> #DIV/0! | Q58: =C58/B58*P58 -> #DIV/0! | S58: =C58/B58*R58 -> #DIV/0! | U58: =C58/B58*T58 -> #DIV/0! | W58: =C58/B58*V58 -> #DIV/0!
A59: Материал | E59: =C59/B59*D59 -> #DIV/0! | G59: =C59/B59*F59 -> #DIV/0! | I59: =C59/B59*H59 -> #DIV/0! | K59: =C59/B59*J59 -> #DIV/0! | M59: =C59/B59*L59 -> #DIV/0! | O59: =C59/B59*N59 -> #DIV/0! | Q59: =C59/B59*P59 -> #DIV/0! | S59: =C59/B59*R59 -> #DIV/0! | U59: =C59/B59*T59 -> #DIV/0! | W59: =C59/B59*V59 -> #DIV/0!
A60: Итого: | D60: =SUM(E3:E59)*1.4 -> #DIV/0! | F60: =SUM(G3:G59)*1.4 -> #DIV/0! | H60: =SUM(I3:I59)*1.4 -> #DIV/0! | J60: =SUM(K3:K59)*1.4 -> #DIV/0! | L60: =SUM(M3:M59)*1.4 -> #DIV/0! | N60: =SUM(O3:O59)*1.4 -> #DIV/0! | P60: =SUM(Q3:Q59)*1.4 -> #DIV/0! | R60: =SUM(S3:S59)*1.4 -> #DIV/0! | T60: =SUM(U3:U59)*1.4 -> #DIV/0! | V60: =SUM(W3:W59)*1.4 -> #DIV/0!

Sheet Прайс
A1: РАСЧЕТ ПРАЙСА
A2: Процедура | B2: Время (ч) | C2: Ст-ть часа | D2: Ст-ть работы | E2: Себестоимость | F2: ПРАЙС
A3: ='Себестоимость'!D1 -> Услуга 1 | C3: =D3/B3 -> #DIV/0! | D3: =F3-E3 -> #DIV/0! | E3: ='Себестоимость'!D60 -> #DIV/0!
A4: ='Себестоимость'!F1 -> Услуга 2 | C4: =D4/B4 -> #DIV/0! | D4: =F4-E4 -> #DIV/0! | E4: ='Себестоимость'!F60 -> #DIV/0!
A5: ='Себестоимость'!H1 -> Услуга 3 | C5: =D5/B5 -> #DIV/0! | D5: =F5-E5 -> #DIV/0! | E5: ='Себестоимость'!H60 -> #DIV/0!
A6: ='Себестоимость'!J1 -> Услуга 4 | C6: =D6/B6 -> #DIV/0! | D6: =F6-E6 -> #DIV/0! | E6: ='Себестоимость'!J60 -> #DIV/0!
A7: ='Себестоимость'!L1 -> Услуга 5 | C7: =D7/B7 -> #DIV/0! | D7: =F7-E7 -> #DIV/0! | E7: ='Себестоимость'!L60 -> #DIV/0!
A8: ='Себестоимость'!N1 -> Услуга 6 | C8: =D8/B8 -> #DIV/0! | D8: =F8-E8 -> #DIV/0! | E8: ='Себестоимость'!N60 -> #DIV/0!
A9: ='Себестоимость'!P1 -> Услуга 7 | C9: =D9/B9 -> #DIV/0! | D9: =F9-E9 -> #DIV/0! | E9: ='Себестоимость'!P60 -> #DIV/0!
A10: ='Себестоимость'!R1 -> Услуга 8 | C10: =D10/B10 -> #DIV/0! | D10: =F10-E10 -> #DIV/0! | E10: ='Себестоимость'!R60 -> #DIV/0!
A11: ='Себестоимость'!T1 -> Услуга 9 | C11: =D11/B11 -> #DIV/0! | D11: =F11-E11 -> #DIV/0! | E11: ='Себестоимость'!T60 -> #DIV/0!
A12: ='Себестоимость'!V1 -> Услуга 10 | C12: =D12/B12 -> #DIV/0! | D12: =F12-E12 -> #DIV/0! | E12: ='Себестоимость'!V60 -> #DIV/0!

Sheet Чистая прибыль
A1: Расходы | B1: Расчет чистой прибыли январь | I1: Расходы | J1: Расчет чистой прибыли май | Q1: Расходы | R1: Расчет чистой прибыли сентябрь
B2: Оказанные услуги | C2: часы | D2: кол-во | E2: себес | F2: руб | G2: Итого | J2: Оказанные услуги | K2: часы | L2: кол-во | M2: себес | N2: руб | O2: Итого | R2: Оказанные услуги | S2: часы | T2: кол-во | U2: себес | V2: руб | W2: Итого
B3: ='Себестоимость'!D1 -> Услуга 1 | C3: =D3*'Прайс'!B3 -> 0 | E3: ='Себестоимость'!D60 -> #DIV/0! | F3: =D3*E3 -> #DIV/0! | G3: =SUM(F3:F12) -> #DIV/0! | J3: ='Себестоимость'!D1 -> Услуга 1 | K3: =D3*'Прайс'!B3 -> 0 | M3: ='Себестоимость'!D60 -> #DIV/0! | N3: =L3*M3 -> #DIV/0! | O3: =SUM(N3:N12) -> #DIV/0! | R3: ='Себестоимость'!D1 -> Услуга 1 | S3: =D3*'Прайс'!B3 -> 0 | U3: ='Себестоимость'!D60 -> #DIV/0! | V3: =T3*U3 -> #DIV/0! | W3: =SUM(V3:V12) -> #DIV/0!
B4: ='Себестоимость'!F1 -> Услуга 2 | C4: =D4*'Прайс'!B4 -> 0 | E4: ='Себестоимость'!F60 -> #DIV/0! | F4: =D4*E4 -> #DIV/0! | J4: ='Себестоимость'!F1 -> Услуга 2 | K4: =D4*'Прайс'!B4 -> 0 | M4: ='Себестоимость'!F60 -> #DIV/0! | N4: =L4*M4 -> #DIV/0! | R4: ='Себестоимость'!F1 -> Услуга 2 | S4: =D4*'Прайс'!B4 -> 0 | U4: ='Себестоимость'!F60 -> #DIV/0! | V4: =T4*U4 -> #DIV/0!
B5: ='Себестоимость'!H1 -> Услуга 3 | C5: =D5*'Прайс'!B5 -> 0 | E5: ='Себестоимость'!H60 -> #DIV/0! | F5: =D5*E5 -> #DIV/0! | J5: ='Себестоимость'!H1 -> Услуга 3 | K5: =D5*'Прайс'!B5 -> 0 | M5: ='Себестоимость'!H60 -> #DIV/0! | N5: =L5*M5 -> #DIV/0! | R5: ='Себестоимость'!H1 -> Услуга 3 | S5: =D5*'Прайс'!B5 -> 0 | U5: ='Себестоимость'!H60 -> #DIV/0! | V5: =T5*U5 -> #DIV/0!
B6: ='Себестоимость'!J1 -> Услуга 4 | C6: =D6*'Прайс'!B6 -> 0 | E6: ='Себестоимость'!J60 -> #DIV/0! | F6: =D6*E6 -> #DIV/0! | J6: ='Себестоимость'!J1 -> Услуга 4 | K6: =D6*'Прайс'!B6 -> 0 | M6: ='Себестоимость'!J60 -> #DIV/0! | N6: =L6*M6 -> #DIV/0! | R6: ='Себестоимость'!J1 -> Услуга 4 | S6: =D6*'Прайс'!B6 -> 0 | U6: ='Себестоимость'!J60 -> #DIV/0! | V6: =T6*U6 -> #DIV/0!
B7: ='Себестоимость'!L1 -> Услуга 5 | C7: =D7*'Прайс'!B7 -> 0 | E7: ='Себестоимость'!L60 -> #DIV/0! | F7: =D7*E7 -> #DIV/0! | J7: ='Себестоимость'!L1 -> Услуга 5 | K7: =D7*'Прайс'!B7 -> 0 | M7: ='Себестоимость'!L60 -> #DIV/0! | N7: =L7*M7 -> #DIV/0! | R7: ='Себестоимость'!L1 -> Услуга 5 | S7: =D7*'Прайс'!B7 -> 0 | U7: ='Себестоимость'!L60 -> #DIV/0! | V7: =T7*U7 -> #DIV/0!
B8: ='Себестоимость'!N1 -> Услуга 6 | C8: =D8*'Прайс'!B8 -> 0 | E8: ='Себестоимость'!N60 -> #DIV/0! | F8: =D8*E8 -> #DIV/0! | J8: ='Себестоимость'!N1 -> Услуга 6 | K8: =D8*'Прайс'!B8 -> 0 | M8: ='Себестоимость'!N60 -> #DIV/0! | N8: =L8*M8 -> #DIV/0! | R8: ='Себестоимость'!N1 -> Услуга 6 | S8: =D8*'Прайс'!B8 -> 0 | U8: ='Себестоимость'!N60 -> #DIV/0! | V8: =T8*U8 -> #DIV/0!
B9: ='Себестоимость'!P1 -> Услуга 7 | C9: =D9*'Прайс'!B9 -> 0 | E9: ='Себестоимость'!P60 -> #DIV/0! | F9: =D9*E9 -> #DIV/0! | J9: ='Себестоимость'!P1 -> Услуга 7 | K9: =D9*'Прайс'!B9 -> 0 | M9: ='Себестоимость'!P60 -> #DIV/0! | N9: =L9*M9 -> #DIV/0! | R9: ='Себестоимость'!P1 -> Услуга 7 | S9: =D9*'Прайс'!B9 -> 0 | U9: ='Себестоимость'!P60 -> #DIV/0! | V9: =T9*U9 -> #DIV/0!
B10: ='Себестоимость'!R1 -> Услуга 8 | C10: =D10*'Прайс'!B10 -> 0 | E10: ='Себестоимость'!R60 -> #DIV/0! | F10: =D10*E10 -> #DIV/0! | J10: ='Себестоимость'!R1 -> Услуга 8 | K10: =D10*'Прайс'!B10 -> 0 | M10: ='Себестоимость'!R60 -> #DIV/0! | N10: =L10*M10 -> #DIV/0! | R10: ='Себестоимость'!R1 -> Услуга 8 | S10: =D10*'Прайс'!B10 -> 0 | U10: ='Себестоимость'!R60 -> #DIV/0! | V10: =T10*U10 -> #DIV/0!
B11: ='Себестоимость'!T1 -> Услуга 9 | C11: =D11*'Прайс'!B11 -> 0 | E11: ='Себестоимость'!T60 -> #DIV/0! | F11: =D11*E11 -> #DIV/0! | J11: ='Себестоимость'!T1 -> Услуга 9 | K11: =D11*'Прайс'!B11 -> 0 | M11: ='Себестоимость'!T60 -> #DIV/0! | N11: =L11*M11 -> #DIV/0! | R11: ='Себестоимость'!T1 -> Услуга 9 | S11: =D11*'Прайс'!B11 -> 0 | U11: ='Себестоимость'!T60 -> #DIV/0! | V11: =T11*U11 -> #DIV/0!
B12: ='Себестоимость'!V1 -> Услуга 10 | C12: =D12*'Прайс'!B12 -> 0 | E12: ='Себестоимость'!V60 -> #DIV/0! | F12: =D12*E12 -> #DIV/0! | J12: ='Себестоимость'!V1 -> Услуга 10 | K12: =D12*'Прайс'!B12 -> 0 | M12: ='Себестоимость'!V60 -> #DIV/0! | N12: =L12*M12 -> #DIV/0! | R12: ='Себестоимость'!V1 -> Услуга 10 | S12: =D12*'Прайс'!B12 -> 0 | U12: ='Себестоимость'!V60 -> #DIV/0! | V12: =T12*U12 -> #DIV/0!
B13: Постоянные | G13: =SUM(F13:F25) -> 0 | J13: Постоянные 1 | O13: =SUM(N13:N25) -> 0 | R13: Постоянные | W13: =SUM(V13:V25) -> 0
B14: Постоянные | J14: Постоянные 2 | R14: Постоянные
B15: Постоянные | J15: Постоянные 3 | R15: Постоянные
B16: Постоянные | J16: Постоянные 4 | R16: Постоянные
B17: Постоянные | J17: Постоянные 5 | R17: Постоянные
B18: Постоянные | J18: Постоянные 6 | R18: Постоянные
B19: Постоянные | J19: Постоянные 7 | R19: Постоянные
B20: Переменные | J20: Переменные 1 | R20: Переменные
B21: Переменные | J21: Переменные 2 | R21: Переменные
B22: Переменные | J22: Переменные 3 | R22: Переменные
B23: Переменные | J23: Переменные 4 | R23: Переменные
B24: Переменные | J24: Переменные 5 | R24: Переменные
B25: Переменные | J25: Переменные 6 | R25: Переменные
B26: Итого расходы | G26: =SUM(G3:G13) -> #DIV/0! | J26: Итого расходы | O26: =SUM(O3:O13) -> #DIV/0! | R26: Итого расходы | W26: =SUM(W3:W13) -> #DIV/0!
A27: Доходы | B27: Услуги | F27: ='Анализ КБ'!B151 -> 0 | G27: =SUM(F27:F29) -> 0 | I27: Доходы | J27: Услуги | N27: ='Анализ КБ'!K151 -> 0 | O27: =SUM(N27:N29) -> 0 | Q27: Доходы | R27: Услуги | V27: ='Анализ КБ'!T151 -> 0 | W27: =SUM(V27:V29) -> 0
B28: Прочее | J28: Прочее | R28: Прочее
B29: Прочее | J29: Прочее | R29: Прочее
A30: Чистая прибыль | B30: Доходы - расходы | G30: =G27-G26 -> #DIV/0! | I30: Чистая прибыль | J30: Доходы - расходы | O30: =O27-O26 -> #DIV/0! | Q30: Чистая прибыль | R30: Доходы - расходы | W30: =W27-W26 -> #DIV/0!
A31: Маржинальность % | B31: (Чист.прибыль/выручка)*100% | G31: =G30/G27*100 -> #DIV/0! | I31: Маржинальность % | J31: (Чист.прибыль/выручка)*100% | O31: =O30/O27*100 -> #DIV/0! | Q31: Маржинальность % | R31: (Чист.прибыль/выручка)*100% | W31: =W30/W27*100 -> #DIV/0!
A32: Средний чек | B32: Выручка/кол-во визитов | G32: =G27/SUM(D3:D12) -> #DIV/0! | I32: Средний чек | J32: Выручка/кол-во визитов | O32: =O27/SUM(L3:L12) -> #DIV/0! | Q32: Средний чек | R32: Выручка/кол-во визитов | W32: =W27/SUM(T3:T12) -> #DIV/0!
A33: Средний час | B33: Чистая прибыль/часы работы | G33: =G30/SUM(C3:C12) -> #DIV/0! | I33: Средний час | J33: Чистая прибыль/часы работы | O33: =O30/SUM(K3:K12) -> #DIV/0! | Q33: Средний час | R33: Чистая прибыль/часы работы | W33: =W30/SUM(S3:S12) -> #DIV/0!
A35: Расходы | B35: Расчет чистой прибыли февраль | I35: Расходы | J35: Расчет чистой прибыли июнь | Q35: Расходы | R35: Расчет чистой прибыли октябрь
B36: Оказанные услуги | C36: часы | D36: кол-во | E36: себес | F36: руб | G36: Итого | J36: Оказанные услуги | K36: часы | L36: кол-во | M36: себес | N36: руб | O36: Итого | R36: Оказанные услуги | S36: часы | T36: кол-во | U36: себес | V36: руб | W36: Итого
B37: ='Себестоимость'!D1 -> Услуга 1 | C37: =D3*'Прайс'!B3 -> 0 | E37: ='Себестоимость'!D60 -> #DIV/0! | F37: =D37*E37 -> #DIV/0! | G37: =SUM(F37:F46) -> #DIV/0! | J37: ='Себестоимость'!D1 -> Услуга 1 | K37: =D3*'Прайс'!B3 -> 0 | M37: ='Себестоимость'!D60 -> #DIV/0! | N37: =L37*M37 -> #DIV/0! | O37: =SUM(N37:N46) -> #DIV/0! | R37: ='Себестоимость'!D1 -> Услуга 1 | S37: =D3*'Прайс'!B3 -> 0 | U37: ='Себестоимость'!D60 -> #DIV/0! | V37: =T37*U37 -> #DIV/0! | W37: =SUM(V37:V46) -> #DIV/0!
B38: ='Себестоимость'!F1 -> Услуга 2 | C38: =D4*'Прайс'!B4 -> 0 | E38: ='Себестоимость'!F60 -> #DIV/0! | F38: =D38*E38 -> #DIV/0! | J38: ='Себестоимость'!F1 -> Услуга 2 | K38: =D4*'Прайс'!B4 -> 0 | M38: ='Себестоимость'!F60 -> #DIV/0! | N38: =L38*M38 -> #DIV/0! | R38: ='Себестоимость'!F1 -> Услуга 2 | S38: =D4*'Прайс'!B4 -> 0 | U38: ='Себестоимость'!F60 -> #DIV/0! | V38: =T38*U38 -> #DIV/0!
B39: ='Себестоимость'!H1 -> Услуга 3 | C39: =D5*'Прайс'!B5 -> 0 | E39: ='Себестоимость'!H60 -> #DIV/0! | F39: =D39*E39 -> #DIV/0! | J39: ='Себестоимость'!H1 -> Услуга 3 | K39: =D5*'Прайс'!B5 -> 0 | M39: ='Себестоимость'!H60 -> #DIV/0! | N39: =L39*M39 -> #DIV/0! | R39: ='Себестоимость'!H1 -> Услуга 3 | S39: =D5*'Прайс'!B5 -> 0 | U39: ='Себестоимость'!H60 -> #DIV/0! | V39: =T39*U39 -> #DIV/0!
B40: ='Себестоимость'!J1 -> Услуга 4 | C40: =D6*'Прайс'!B6 -> 0 | E40: ='Себестоимость'!J60 -> #DIV/0! | F40: =D40*E40 -> #DIV/0! | J40: ='Себестоимость'!J1 -> Услуга 4 | K40: =D6*'Прайс'!B6 -> 0 | M40: ='Себестоимость'!J60 -> #DIV/0! | N40: =L40*M40 -> #DIV/0! | R40: ='Себестоимость'!J1 -> Услуга 4 | S40: =D6*'Прайс'!B6 -> 0 | U40: ='Себестоимость'!J60 -> #DIV/0! | V40: =T40*U40 -> #DIV/0!
B41: ='Себестоимость'!L1 -> Услуга 5 | C41: =D7*'Прайс'!B7 -> 0 | E41: ='Себестоимость'!L60 -> #DIV/0! | F41: =D41*E41 -> #DIV/0! | J41: ='Себестоимость'!L1 -> Услуга 5 | K41: =D7*'Прайс'!B7 -> 0 | M41: ='Себестоимость'!L60 -> #DIV/0! | N41: =L41*M41 -> #DIV/0! | R41: ='Себестоимость'!L1 -> Услуга 5 | S41: =D7*'Прайс'!B7 -> 0 | U41: ='Себестоимость'!L60 -> #DIV/0! | V41: =T41*U41 -> #DIV/0!
...

Sheet ЧП за год
A1: Расходы | B1: Расчет чистой прибыли за год
B2: Оказанные услуги | C2: часы | D2: кол-во | E2: себес | F2: руб | G2: Итого
B3: ='Себестоимость'!D1 -> Услуга 1 | C3: =SUM('Чистая прибыль'!C3+'Чистая прибыль'!C37+'Чистая прибыль'!C71+'Чистая прибыль'!C105+'Чистая прибыль'!K3+'Чистая прибыль'!K37+'Чистая прибыль'!K71+'Чистая прибыль'!K105+'Чистая прибыль'!S3+'Чистая прибыль'!S37+'Чистая прибыль'!S71+'Чистая прибыль'!S105) -> 0 | D3: =SUM('Чистая прибыль'!D3+'Чистая прибыль'!D37+'Чистая прибыль'!D71+'Чистая прибыль'!D105+'Чистая прибыль'!L3+'Чистая прибыль'!L37+'Чистая прибыль'!L71+'Чистая прибыль'!T3+'Чистая прибыль'!T37+'Чистая прибыль'!T71+'Чистая прибыль'!T105) -> 0 | E3: ='Себестоимость'!D60 -> #DIV/0! | F3: =D3*E3 -> #DIV/0! | G3: =SUM(F3:F12) -> #DIV/0!
B4: ='Себестоимость'!F1 -> Услуга 2 | C4: =SUM('Чистая прибыль'!C4+'Чистая прибыль'!C38+'Чистая прибыль'!C72+'Чистая прибыль'!C106+'Чистая прибыль'!K4+'Чистая прибыль'!K38+'Чистая прибыль'!K72+'Чистая прибыль'!K106+'Чистая прибыль'!S4+'Чистая прибыль'!S38+'Чистая прибыль'!S72+'Чистая прибыль'!S106) -> 0 | D4: =SUM('Чистая прибыль'!D4+'Чистая прибыль'!D38+'Чистая прибыль'!D72+'Чистая прибыль'!D106+'Чистая прибыль'!L4+'Чистая прибыль'!T4+'Чистая прибыль'!L38+'Чистая прибыль'!T38+'Чистая прибыль'!L72+'Чистая прибыль'!T72+'Чистая прибыль'!L106+'Чистая прибыль'!T106) -> 0 | E4: ='Себестоимость'!F60 -> #DIV/0! | F4: =D4*E4 -> #DIV/0!
B5: ='Себестоимость'!H1 -> Услуга 3 | C5: =SUM('Чистая прибыль'!C5+'Чистая прибыль'!C39+'Чистая прибыль'!C73+'Чистая прибыль'!K5+'Чистая прибыль'!K39+'Чистая прибыль'!K73+'Чистая прибыль'!K107+'Чистая прибыль'!C107+'Чистая прибыль'!S5+'Чистая прибыль'!S39+'Чистая прибыль'!S73+'Чистая прибыль'!S107) -> 0 | D5: =SUM('Чистая прибыль'!D5+'Чистая прибыль'!D39+'Чистая прибыль'!D73+'Чистая прибыль'!D107+'Чистая прибыль'!L5+'Чистая прибыль'!L39+'Чистая прибыль'!L73+'Чистая прибыль'!K107+'Чистая прибыль'!T5+'Чистая прибыль'!T39+'Чистая прибыль'!T73+'Чистая прибыль'!T107) -> 0 | E5: ='Себестоимость'!H60 -> #DIV/0! | F5: =D5*E5 -> #DIV/0!
B6: ='Себестоимость'!J1 -> Услуга 4 | C6: =SUM('Чистая прибыль'!C6+'Чистая прибыль'!C40+'Чистая прибыль'!C74+'Чистая прибыль'!C108+'Чистая прибыль'!K108+'Чистая прибыль'!K74+'Чистая прибыль'!K40+'Чистая прибыль'!K6+'Чистая прибыль'!S6+'Чистая прибыль'!S40+'Чистая прибыль'!S74+'Чистая прибыль'!S108) -> 0 | D6: =SUM('Чистая прибыль'!D6+'Чистая прибыль'!D40+'Чистая прибыль'!D74+'Чистая прибыль'!D108+'Чистая прибыль'!L6+'Чистая прибыль'!L40+'Чистая прибыль'!L74+'Чистая прибыль'!K108+'Чистая прибыль'!T6+'Чистая прибыль'!T40+'Чистая прибыль'!T74+'Чистая прибыль'!T108) -> 0 | E6: ='Себестоимость'!J60 -> #DIV/0! | F6: =D6*E6 -> #DIV/0!
B7: ='Себестоимость'!L1 -> Услуга 5 | C7: =SUM('Чистая прибыль'!C7+'Чистая прибыль'!C41+'Чистая прибыль'!C75+'Чистая прибыль'!C109+'Чистая прибыль'!K109+'Чистая прибыль'!K75+'Чистая прибыль'!K41+'Чистая прибыль'!K7+'Чистая прибыль'!S7+'Чистая прибыль'!S41+'Чистая прибыль'!S75+'Чистая прибыль'!S109) -> 0 | D7: =SUM('Чистая прибыль'!D7+'Чистая прибыль'!D41+'Чистая прибыль'!D75+'Чистая прибыль'!D109+'Чистая прибыль'!L7+'Чистая прибыль'!L41+'Чистая прибыль'!L75+'Чистая прибыль'!K109+'Чистая прибыль'!T7+'Чистая прибыль'!T41+'Чистая прибыль'!T75+'Чистая прибыль'!T109) -> 0 | E7: ='Себестоимость'!L60 -> #DIV/0! | F7: =D7*E7 -> #DIV/0!
B8: ='Себестоимость'!N1 -> Услуга 6 | C8: =SUM('Чистая прибыль'!C8+'Чистая прибыль'!C42+'Чистая прибыль'!C76+'Чистая прибыль'!C110+'Чистая прибыль'!K8+'Чистая прибыль'!K42+'Чистая прибыль'!K76+'Чистая прибыль'!K110+'Чистая прибыль'!S8+'Чистая прибыль'!S42+'Чистая прибыль'!S76+'Чистая прибыль'!S110) -> 0 | D8: =SUM('Чистая прибыль'!D8+'Чистая прибыль'!D42+'Чистая прибыль'!D76+'Чистая прибыль'!D110+'Чистая прибыль'!L8+'Чистая прибыль'!L42+'Чистая прибыль'!L76+'Чистая прибыль'!K110+'Чистая прибыль'!T8+'Чистая прибыль'!T42+'Чистая прибыль'!T76+'Чистая прибыль'!T110) -> 0 | E8: ='Себестоимость'!N60 -> #DIV/0! | F8: =D8*E8 -> #DIV/0!
B9: ='Себестоимость'!P1 -> Услуга 7 | C9: =SUM('Чистая прибыль'!C9+'Чистая прибыль'!C43+'Чистая прибыль'!C77+'Чистая прибыль'!C111+'Чистая прибыль'!K9+'Чистая прибыль'!K43+'Чистая прибыль'!K77+'Чистая прибыль'!K111+'Чистая прибыль'!S9+'Чистая прибыль'!S43+'Чистая прибыль'!S77+'Чистая прибыль'!S111) -> 0 | D9: =SUM('Чистая прибыль'!D9+'Чистая прибыль'!D43+'Чистая прибыль'!D77+'Чистая прибыль'!D111+'Чистая прибыль'!L9+'Чистая прибыль'!L43+'Чистая прибыль'!L77+'Чистая прибыль'!K111+'Чистая прибыль'!T9+'Чистая прибыль'!T43+'Чистая прибыль'!T77+'Чистая прибыль'!T111) -> 0 | E9: ='Себестоимость'!P60 -> #DIV/0! | F9: =D9*E9 -> #DIV/0!
B10: ='Себестоимость'!R1 -> Услуга 8 | C10: =SUM('Чистая прибыль'!C10+'Чистая прибыль'!C44+'Чистая прибыль'!C78+'Чистая прибыль'!C112+'Чистая прибыль'!K10+'Чистая прибыль'!K44+'Чистая прибыль'!K78+'Чистая прибыль'!K112+'Чистая прибыль'!S10+'Чистая прибыль'!S44+'Чистая прибыль'!S78+'Чистая прибыль'!S1120) -> 0 | D10: =SUM('Чистая прибыль'!D10+'Чистая прибыль'!D44+'Чистая прибыль'!D78+'Чистая прибыль'!D112+'Чистая прибыль'!L10+'Чистая прибыль'!L44+'Чистая прибыль'!L78+'Чистая прибыль'!K112+'Чистая прибыль'!T10+'Чистая прибыль'!T44+'Чистая прибыль'!T78+'Чистая прибыль'!T112) -> 0 | E10: ='Себестоимость'!R60 -> #DIV/0! | F10: =D10*E10 -> #DIV/0!
B11: ='Себестоимость'!T1 -> Услуга 9 | C11: =SUM('Чистая прибыль'!C11+'Чистая прибыль'!C45+'Чистая прибыль'!C79+'Чистая прибыль'!C113+'Чистая прибыль'!K11+'Чистая прибыль'!K45+'Чистая прибыль'!K79+'Чистая прибыль'!K113+'Чистая прибыль'!S11+'Чистая прибыль'!S45+'Чистая прибыль'!S79+'Чистая прибыль'!S113) -> 0 | D11: =SUM('Чистая прибыль'!D11+'Чистая прибыль'!D45+'Чистая прибыль'!D79+'Чистая прибыль'!D113+'Чистая прибыль'!L11+'Чистая прибыль'!L45+'Чистая прибыль'!L79+'Чистая прибыль'!K113+'Чистая прибыль'!T11+'Чистая прибыль'!T45+'Чистая прибыль'!T79+'Чистая прибыль'!T113) -> 0 | E11: ='Себестоимость'!T60 -> #DIV/0! | F11: =D11*E11 -> #DIV/0!
B12: ='Себестоимость'!V1 -> Услуга 10 | C12: =SUM('Чистая прибыль'!C12+'Чистая прибыль'!C46+'Чистая прибыль'!C80+'Чистая прибыль'!C114+'Чистая прибыль'!K12+'Чистая прибыль'!K46+'Чистая прибыль'!K80+'Чистая прибыль'!K114+'Чистая прибыль'!S12+'Чистая прибыль'!S46+'Чистая прибыль'!S80+'Чистая прибыль'!S114) -> 0 | D12: =SUM('Чистая прибыль'!D12+'Чистая прибыль'!D46+'Чистая прибыль'!D80+'Чистая прибыль'!D114+'Чистая прибыль'!L12+'Чистая прибыль'!L46+'Чистая прибыль'!L80+'Чистая прибыль'!K114+'Чистая прибыль'!T12+'Чистая прибыль'!T46+'Чистая прибыль'!T80+'Чистая прибыль'!T114) -> 0 | E12: ='Себестоимость'!V60 -> #DIV/0! | F12: =D12*E12 -> #DIV/0!
B13: Постоянные | G13: =SUM('Чистая прибыль'!G13+'Чистая прибыль'!G47+'Чистая прибыль'!G81+'Чистая прибыль'!G115+'Чистая прибыль'!O13+'Чистая прибыль'!O47+'Чистая прибыль'!O81+'Чистая прибыль'!O115+'Чистая прибыль'!W13+'Чистая прибыль'!W47+'Чистая прибыль'!W81+'Чистая прибыль'!W115) -> 0
B14: Переменные
B15: Итого расходы | G15: =SUM(G3:G13) -> #DIV/0!
A16: Доходы | B16: Услуги | G16: =SUM('Чистая прибыль'!G27+'Чистая прибыль'!G61+'Чистая прибыль'!G95+'Чистая прибыль'!G129+'Чистая прибыль'!O27+'Чистая прибыль'!O61+'Чистая прибыль'!O95+'Чистая прибыль'!O129+'Чистая прибыль'!W27+'Чистая прибыль'!W61+'Чистая прибыль'!W95+'Чистая прибыль'!W129) -> 0
B17: Прочее
B18: Прочее
A19: Чистая прибыль | B19: Доходы - расходы | G19: =G16-G15 -> #DIV/0!
A20: Маржинальность % | B20: (Чист.прибыль/выручка)*100% | G20: =G19/G16*100 -> #DIV/0!
A21: Средний чек | B21: Выручка/кол-во визитов | G21: =G16/SUM(D3:D12) -> #DIV/0!
A22: Средний час | B22: Чистая прибыль/часы работы | G22: =G19/SUM(C3:C12) -> #DIV/0!
A23: Ср. прибыль в месяц | B23: Чистая прибыль/12 | G23: =G19/12 -> #DIV/0!
